Traceback (most recent call last):
  File "/home/pi/hikari/fire_osc.py", line 155, in <module>
    asyncio.run(init_main())
  File "/usr/lib/python3.9/asyncio/runners.py", line 44, in run
    return loop.run_until_complete(main)
  File "/usr/lib/python3.9/asyncio/base_events.py", line 642, in run_until_complete
    return future.result()
  File "/home/pi/hikari/fire_osc.py", line 148, in init_main
    transport, protocol = await server.create_serve_endpoint()  # Create datagram endpoint and start serving
  File "/usr/lib/python3.9/asyncio/base_events.py", line 1363, in create_datagram_endpoint
    raise exceptions[0]
  File "/usr/lib/python3.9/asyncio/base_events.py", line 1347, in create_datagram_endpoint
    sock.bind(local_address)
OSError: [Errno 98] Address already in use
